I'm sorry, but an uncaught exception occurred.

While running game code:
  File "game/places.rpy", line 5, in script call
    call go_to_computer()
  File "game/base_of_operations.rpy", line 3, in script
    $ is_online_store_unlocked = regions_variable.object['OnlineStore'].unlocked
  File "game/base_of_operations.rpy", line 3, in <module>
    $ is_online_store_unlocked = regions_variable.object['OnlineStore'].unlocked
                                 ^^^^^^^^^^^^^^^^^^^^^^^^^^^^^^^^^^^^^^^^^^^^^^^
AttributeError: 'RevertableDict' object has no attribute 'unlocked'

-- Full Traceback ------------------------------------------------------------

Traceback (most recent call last):
  File "game/places.rpy", line 5, in script call
    call go_to_computer()
  File "game/base_of_operations.rpy", line 3, in script
    $ is_online_store_unlocked = regions_variable.object['OnlineStore'].unlocked
  File "renpy/ast.py", line 1187, in execute
    renpy.python.py_exec_bytecode(self.code.bytecode, self.hide, store=self.store)
    ~~~~~~~~~~~~~~~~~~~~~~~~~~~~~^^^^^^^^^^^^^^^^^^^^^^^^^^^^^^^^^^^^^^^^^^^^^^^^^
  File "renpy/python.py", line 1260, in py_exec_bytecode
    exec(bytecode, globals, locals)
    ~~~~^^^^^^^^^^^^^^^^^^^^^^^^^^^
  File "game/base_of_operations.rpy", line 3, in <module>
    $ is_online_store_unlocked = regions_variable.object['OnlineStore'].unlocked
                                 ^^^^^^^^^^^^^^^^^^^^^^^^^^^^^^^^^^^^^^^^^^^^^^^
AttributeError: 'RevertableDict' object has no attribute 'unlocked'

Windows-11-10.0.26120-SP0 AMD64
Ren'Py 8.4.1.25072401
Protectors 1.0
Tue Sep 23 17:38:45 2025
