I'm sorry, but an uncaught exception occurred.

While running game code:
  File "game/places.rpy", line 16, in script call
    call go_to_computer()
  File "game/base_of_operations.rpy", line 5, in script call
    call see_all_missions(1)
  File "game/base_of_operations.rpy", line 60, in script call
    call see_all_missions(1)
  File "game/places.rpy", line 18, in script call
    call base_travel_menu()
  File "game/places.rpy", line 36, in script call
    call rest()
  File "game/places.rpy", line 36, in script call
    call rest()
  File "game/places.rpy", line 36, in script call
    call rest()
  [Previous line repeated 1 more time]
  File "game/places.rpy", line 38, in script call
    call base_travel_menu()
  File "game/places.rpy", line 38, in script call
    call base_travel_menu()
  File "game/places.rpy", line 16, in script call
    call go_to_computer()
  File "game/base_of_operations.rpy", line 7, in script call
    call check_my_missions()
  File "game/places.rpy", line 16, in script call
    call go_to_computer()
  File "game/base_of_operations.rpy", line 5, in script call
    call see_all_missions(1)
  File "game/base_of_operations.rpy", line 60, in script call
    call see_all_missions(1)
  File "game/places.rpy", line 18, in script call
    call base_travel_menu()
  File "game/places.rpy", line 36, in script call
    call rest()
  File "game/places.rpy", line 36, in script call
    call rest()
  File "game/places.rpy", line 36, in script call
    call rest()
  [Previous line repeated 1 more time]
  File "game/places.rpy", line 38, in script call
    call base_travel_menu()
  File "game/places.rpy", line 38, in script call
    call base_travel_menu()
  File "game/places.rpy", line 16, in script call
    call go_to_computer()
  File "game/base_of_operations.rpy", line 7, in script call
    call check_my_missions()
ScriptError: could not find label 'check_my_missions'.

-- Full Traceback ------------------------------------------------------------

Full traceback:
  File "game/places.rpy", line 16, in script call
    call go_to_computer()
  File "game/base_of_operations.rpy", line 5, in script call
    call see_all_missions(1)
  File "game/base_of_operations.rpy", line 60, in script call
    call see_all_missions(1)
  File "game/places.rpy", line 18, in script call
    call base_travel_menu()
  File "game/places.rpy", line 36, in script call
    call rest()
  File "game/places.rpy", line 36, in script call
    call rest()
  File "game/places.rpy", line 36, in script call
    call rest()
  [Previous line repeated 1 more time]
  File "game/places.rpy", line 38, in script call
    call base_travel_menu()
  File "game/places.rpy", line 38, in script call
    call base_travel_menu()
  File "game/places.rpy", line 16, in script call
    call go_to_computer()
  File "game/base_of_operations.rpy", line 7, in script call
    call check_my_missions()
  File "D:\renpy\renpy-8.3.7-sdk\renpy\ast.py", line 1427, in execute
    rv = renpy.game.context().call(label, return_site=self.next.name)
  File "game/places.rpy", line 16, in script call
    call go_to_computer()
  File "game/base_of_operations.rpy", line 5, in script call
    call see_all_missions(1)
  File "game/base_of_operations.rpy", line 60, in script call
    call see_all_missions(1)
  File "game/places.rpy", line 18, in script call
    call base_travel_menu()
  File "game/places.rpy", line 36, in script call
    call rest()
  File "game/places.rpy", line 36, in script call
    call rest()
  File "game/places.rpy", line 36, in script call
    call rest()
  [Previous line repeated 1 more time]
  File "game/places.rpy", line 38, in script call
    call base_travel_menu()
  File "game/places.rpy", line 38, in script call
    call base_travel_menu()
  File "game/places.rpy", line 16, in script call
    call go_to_computer()
  File "game/base_of_operations.rpy", line 7, in script call
    call check_my_missions()
  File "D:\renpy\renpy-8.3.7-sdk\renpy\script.py", line 1103, in lookup
    raise ScriptError("could not find label '%s'." % str(original))
ScriptError: could not find label 'check_my_missions'.

Windows-10-10.0.26120 AMD64
Ren'Py 8.3.7.25031702
Protectors 1.0
Thu Aug  7 00:07:20 2025
