I'm sorry, but an uncaught exception occurred.

While running game code:
  File "game/script.rpy", line 30, in script
    $ testing_things()
  File "game/script.rpy", line 30, in <module>
    $ testing_things()
  File "game/functions.rpy", line 281, in testing_things
    renpy.say(None, str(mission.name))
AttributeError: 'Mission' object has no attribute 'name'

-- Full Traceback ------------------------------------------------------------

Full traceback:
  File "game/script.rpy", line 30, in script
    $ testing_things()
  File "D:\renpy\renpy-8.3.7-sdk\renpy\ast.py", line 834, in execute
    renpy.python.py_exec_bytecode(self.code.bytecode, self.hide, store=self.store)
  File "D:\renpy\renpy-8.3.7-sdk\renpy\python.py", line 1187, in py_exec_bytecode
    exec(bytecode, globals, locals)
  File "game/script.rpy", line 30, in <module>
    $ testing_things()
  File "game/functions.rpy", line 281, in testing_things
    renpy.say(None, str(mission.name))
AttributeError: 'Mission' object has no attribute 'name'

Windows-10-10.0.26120 AMD64
Ren'Py 8.3.7.25031702
Protectors 1.0
Fri Aug  1 10:47:19 2025
