I'm sorry, but an uncaught exception occurred.

While running game code:
  File "game/places.rpy", line 17, in script call
    call check_my_missions()
  File "game/places.rpy", line 17, in script call
    call check_my_missions()
ScriptError: could not find label 'check_my_missions'.

-- Full Traceback ------------------------------------------------------------

Full traceback:
  File "game/places.rpy", line 17, in script call
    call check_my_missions()
  File "D:\renpy\renpy-8.3.7-sdk\renpy\ast.py", line 1427, in execute
    rv = renpy.game.context().call(label, return_site=self.next.name)
  File "game/places.rpy", line 17, in script call
    call check_my_missions()
  File "D:\renpy\renpy-8.3.7-sdk\renpy\script.py", line 1103, in lookup
    raise ScriptError("could not find label '%s'." % str(original))
ScriptError: could not find label 'check_my_missions'.

Windows-10-10.0.26120 AMD64
Ren'Py 8.3.7.25031702
Protectors 1.0
Wed Jul 30 22:28:33 2025
